Internal Server Error: /media/
Traceback (most recent call last):
  File "/home/pije76/.virtualenvs/justdial/lib/python3.6/site-packages/django/db/models/fields/__init__.py", line 1772, in get_prep_value
    return int(value)
ValueError: invalid literal for int() with base 10: 'media'

The above exception was the direct cause of the following exception:

Traceback (most recent call last):
  File "/home/pije76/.virtualenvs/justdial/lib/python3.6/site-packages/django/core/handlers/exception.py", line 34, in inner
    response = get_response(request)
  File "/home/pije76/.virtualenvs/justdial/lib/python3.6/site-packages/django/core/handlers/base.py", line 115, in _get_response
    response = self.process_exception_by_middleware(e, request)
  File "/home/pije76/.virtualenvs/justdial/lib/python3.6/site-packages/django/core/handlers/base.py", line 113, in _get_response
    response = wrapped_callback(request, *callback_args, **callback_kwargs)
  File "/var/www/html/justdial/listing/views.py", line 40, in region_list
    country_name = Country.objects.filter(id=country_id)
  File "/home/pije76/.virtualenvs/justdial/lib/python3.6/site-packages/django/db/models/manager.py", line 82, in manager_method
    return getattr(self.get_queryset(), name)(*args, **kwargs)
  File "/home/pije76/.virtualenvs/justdial/lib/python3.6/site-packages/django/db/models/query.py", line 904, in filter
    return self._filter_or_exclude(False, *args, **kwargs)
  File "/home/pije76/.virtualenvs/justdial/lib/python3.6/site-packages/django/db/models/query.py", line 923, in _filter_or_exclude
    clone.query.add_q(Q(*args, **kwargs))
  File "/home/pije76/.virtualenvs/justdial/lib/python3.6/site-packages/django/db/models/sql/query.py", line 1350, in add_q
    clause, _ = self._add_q(q_object, self.used_aliases)
  File "/home/pije76/.virtualenvs/justdial/lib/python3.6/site-packages/django/db/models/sql/query.py", line 1381, in _add_q
    check_filterable=check_filterable,
  File "/home/pije76/.virtualenvs/justdial/lib/python3.6/site-packages/django/db/models/sql/query.py", line 1311, in build_filter
    condition = self.build_lookup(lookups, col, value)
  File "/home/pije76/.virtualenvs/justdial/lib/python3.6/site-packages/django/db/models/sql/query.py", line 1165, in build_lookup
    lookup = lookup_class(lhs, rhs)
  File "/home/pije76/.virtualenvs/justdial/lib/python3.6/site-packages/django/db/models/lookups.py", line 22, in __init__
    self.rhs = self.get_prep_lookup()
  File "/home/pije76/.virtualenvs/justdial/lib/python3.6/site-packages/django/db/models/lookups.py", line 72, in get_prep_lookup
    return self.lhs.output_field.get_prep_value(self.rhs)
  File "/home/pije76/.virtualenvs/justdial/lib/python3.6/site-packages/django/db/models/fields/__init__.py", line 1776, in get_prep_value
    ) from e
ValueError: Field 'id' expected a number but got 'media'.
Internal Server Error: /united-states/1981/40/2/judul-2/
Traceback (most recent call last):
  File "/home/pije76/.virtualenvs/justdial/lib/python3.6/site-packages/django/template/base.py", line 469, in parse
    compile_func = self.tags[command]
KeyError: 'thumbnail'

During handling of the above exception, another exception occurred:

Traceback (most recent call last):
  File "/home/pije76/.virtualenvs/justdial/lib/python3.6/site-packages/django/core/handlers/exception.py", line 34, in inner
    response = get_response(request)
  File "/home/pije76/.virtualenvs/justdial/lib/python3.6/site-packages/django/core/handlers/base.py", line 115, in _get_response
    response = self.process_exception_by_middleware(e, request)
  File "/home/pije76/.virtualenvs/justdial/lib/python3.6/site-packages/django/core/handlers/base.py", line 113, in _get_response
    response = wrapped_callback(request, *callback_args, **callback_kwargs)
  File "/var/www/html/justdial/listing/views.py", line 106, in listing_detail
    return render(request, 'view_ad.html', context)
  File "/home/pije76/.virtualenvs/justdial/lib/python3.6/site-packages/django/shortcuts.py", line 19, in render
    content = loader.render_to_string(template_name, context, request, using=using)
  File "/home/pije76/.virtualenvs/justdial/lib/python3.6/site-packages/django/template/loader.py", line 61, in render_to_string
    template = get_template(template_name, using=using)
  File "/home/pije76/.virtualenvs/justdial/lib/python3.6/site-packages/django/template/loader.py", line 15, in get_template
    return engine.get_template(template_name)
  File "/home/pije76/.virtualenvs/justdial/lib/python3.6/site-packages/django/template/backends/django.py", line 34, in get_template
    return Template(self.engine.get_template(template_name), self)
  File "/home/pije76/.virtualenvs/justdial/lib/python3.6/site-packages/django/template/engine.py", line 143, in get_template
    template, origin = self.find_template(template_name)
  File "/home/pije76/.virtualenvs/justdial/lib/python3.6/site-packages/django/template/engine.py", line 125, in find_template
    template = loader.get_template(name, skip=skip)
  File "/home/pije76/.virtualenvs/justdial/lib/python3.6/site-packages/django/template/loaders/base.py", line 30, in get_template
    contents, origin, origin.template_name, self.engine,
  File "/home/pije76/.virtualenvs/justdial/lib/python3.6/site-packages/django/template/base.py", line 156, in __init__
    self.nodelist = self.compile_nodelist()
  File "/home/pije76/.virtualenvs/justdial/lib/python3.6/site-packages/django/template/base.py", line 194, in compile_nodelist
    return parser.parse()
  File "/home/pije76/.virtualenvs/justdial/lib/python3.6/site-packages/django/template/base.py", line 477, in parse
    raise self.error(token, e)
  File "/home/pije76/.virtualenvs/justdial/lib/python3.6/site-packages/django/template/base.py", line 475, in parse
    compiled_result = compile_func(self, token)
  File "/home/pije76/.virtualenvs/justdial/lib/python3.6/site-packages/django/template/loader_tags.py", line 266, in do_extends
    nodelist = parser.parse()
  File "/home/pije76/.virtualenvs/justdial/lib/python3.6/site-packages/django/template/base.py", line 477, in parse
    raise self.error(token, e)
  File "/home/pije76/.virtualenvs/justdial/lib/python3.6/site-packages/django/template/base.py", line 475, in parse
    compiled_result = compile_func(self, token)
  File "/home/pije76/.virtualenvs/justdial/lib/python3.6/site-packages/django/template/loader_tags.py", line 209, in do_block
    nodelist = parser.parse(('endblock',))
  File "/home/pije76/.virtualenvs/justdial/lib/python3.6/site-packages/django/template/base.py", line 477, in parse
    raise self.error(token, e)
  File "/home/pije76/.virtualenvs/justdial/lib/python3.6/site-packages/django/template/base.py", line 475, in parse
    compiled_result = compile_func(self, token)
  File "/home/pije76/.virtualenvs/justdial/lib/python3.6/site-packages/django/template/defaulttags.py", line 811, in do_for
    nodelist_loop = parser.parse(('empty', 'endfor',))
  File "/home/pije76/.virtualenvs/justdial/lib/python3.6/site-packages/django/template/base.py", line 471, in parse
    self.invalid_block_tag(token, command, parse_until)
  File "/home/pije76/.virtualenvs/justdial/lib/python3.6/site-packages/django/template/base.py", line 527, in invalid_block_tag
    get_text_list(["'%s'" % p for p in parse_until], 'or'),
django.template.exceptions.TemplateSyntaxError: Invalid block tag on line 30: 'thumbnail', expected 'empty' or 'endfor'. Did you forget to register or load this tag?
Internal Server Error: /admin/listing/listing/2/change/
Traceback (most recent call last):
  File "/home/pije76/.virtualenvs/justdial/lib/python3.6/site-packages/django/core/handlers/exception.py", line 34, in inner
    response = get_response(request)
  File "/home/pije76/.virtualenvs/justdial/lib/python3.6/site-packages/django/core/handlers/base.py", line 100, in _get_response
    resolver_match = resolver.resolve(request.path_info)
  File "/home/pije76/.virtualenvs/justdial/lib/python3.6/site-packages/django/urls/resolvers.py", line 544, in resolve
    for pattern in self.url_patterns:
  File "/home/pije76/.virtualenvs/justdial/lib/python3.6/site-packages/django/utils/functional.py", line 48, in __get__
    res = instance.__dict__[self.name] = self.func(instance)
  File "/home/pije76/.virtualenvs/justdial/lib/python3.6/site-packages/django/urls/resolvers.py", line 588, in url_patterns
    patterns = getattr(self.urlconf_module, "urlpatterns", self.urlconf_module)
  File "/home/pije76/.virtualenvs/justdial/lib/python3.6/site-packages/django/utils/functional.py", line 48, in __get__
    res = instance.__dict__[self.name] = self.func(instance)
  File "/home/pije76/.virtualenvs/justdial/lib/python3.6/site-packages/django/urls/resolvers.py", line 581, in urlconf_module
    return import_module(self.urlconf_name)
  File "/home/pije76/.virtualenvs/justdial/lib/python3.6/importlib/__init__.py", line 126, in import_module
    return _bootstrap._gcd_import(name[level:], package, level)
  File "<frozen importlib._bootstrap>", line 994, in _gcd_import
  File "<frozen importlib._bootstrap>", line 971, in _find_and_load
  File "<frozen importlib._bootstrap>", line 955, in _find_and_load_unlocked
  File "<frozen importlib._bootstrap>", line 665, in _load_unlocked
  File "<frozen importlib._bootstrap_external>", line 678, in exec_module
  File "<frozen importlib._bootstrap>", line 219, in _call_with_frames_removed
  File "/var/www/html/justdial/justdial/urls.py", line 30, in <module>
    url(r'^ajax_select/', include(ajax_select_urls)),
NameError: name 'url' is not defined
Internal Server Error: /admin/listing/listing/2/change/
Traceback (most recent call last):
  File "/home/pije76/.virtualenvs/justdial/lib/python3.6/site-packages/django/core/handlers/exception.py", line 34, in inner
    response = get_response(request)
  File "/home/pije76/.virtualenvs/justdial/lib/python3.6/site-packages/debug_toolbar/middleware.py", line 92, in __call__
    panel.generate_stats(request, response)
  File "/home/pije76/.virtualenvs/justdial/lib/python3.6/site-packages/debug_toolbar/panels/request.py", line 43, in generate_stats
    match = resolve(request.path)
  File "/home/pije76/.virtualenvs/justdial/lib/python3.6/site-packages/django/urls/base.py", line 25, in resolve
    return get_resolver(urlconf).resolve(path)
  File "/home/pije76/.virtualenvs/justdial/lib/python3.6/site-packages/django/urls/resolvers.py", line 544, in resolve
    for pattern in self.url_patterns:
  File "/home/pije76/.virtualenvs/justdial/lib/python3.6/site-packages/django/utils/functional.py", line 48, in __get__
    res = instance.__dict__[self.name] = self.func(instance)
  File "/home/pije76/.virtualenvs/justdial/lib/python3.6/site-packages/django/urls/resolvers.py", line 588, in url_patterns
    patterns = getattr(self.urlconf_module, "urlpatterns", self.urlconf_module)
  File "/home/pije76/.virtualenvs/justdial/lib/python3.6/site-packages/django/utils/functional.py", line 48, in __get__
    res = instance.__dict__[self.name] = self.func(instance)
  File "/home/pije76/.virtualenvs/justdial/lib/python3.6/site-packages/django/urls/resolvers.py", line 581, in urlconf_module
    return import_module(self.urlconf_name)
  File "/home/pije76/.virtualenvs/justdial/lib/python3.6/importlib/__init__.py", line 126, in import_module
    return _bootstrap._gcd_import(name[level:], package, level)
  File "<frozen importlib._bootstrap>", line 994, in _gcd_import
  File "<frozen importlib._bootstrap>", line 971, in _find_and_load
  File "<frozen importlib._bootstrap>", line 955, in _find_and_load_unlocked
  File "<frozen importlib._bootstrap>", line 665, in _load_unlocked
  File "<frozen importlib._bootstrap_external>", line 678, in exec_module
  File "<frozen importlib._bootstrap>", line 219, in _call_with_frames_removed
  File "/var/www/html/justdial/justdial/urls.py", line 30, in <module>
    url(r'^ajax_select/', include(ajax_select_urls)),
NameError: name 'url' is not defined
Internal Server Error: /ajax_select/ajax_lookup/category
Traceback (most recent call last):
  File "/home/pije76/.virtualenvs/justdial/lib/python3.6/site-packages/django/core/handlers/exception.py", line 34, in inner
    response = get_response(request)
  File "/home/pije76/.virtualenvs/justdial/lib/python3.6/site-packages/django/core/handlers/base.py", line 115, in _get_response
    response = self.process_exception_by_middleware(e, request)
  File "/home/pije76/.virtualenvs/justdial/lib/python3.6/site-packages/django/core/handlers/base.py", line 113, in _get_response
    response = wrapped_callback(request, *callback_args, **callback_kwargs)
  File "/home/pije76/.virtualenvs/justdial/lib/python3.6/site-packages/ajax_select/views.py", line 36, in ajax_lookup
    instances = lookup.get_query(query, request)
  File "/var/www/html/justdial/listing/lookups.py", line 26, in get_query
    return self.model.objects.filter(category__icontains=q).order_by('category')[:50]
  File "/home/pije76/.virtualenvs/justdial/lib/python3.6/site-packages/django/db/models/manager.py", line 82, in manager_method
    return getattr(self.get_queryset(), name)(*args, **kwargs)
  File "/home/pije76/.virtualenvs/justdial/lib/python3.6/site-packages/django/db/models/query.py", line 904, in filter
    return self._filter_or_exclude(False, *args, **kwargs)
  File "/home/pije76/.virtualenvs/justdial/lib/python3.6/site-packages/django/db/models/query.py", line 923, in _filter_or_exclude
    clone.query.add_q(Q(*args, **kwargs))
  File "/home/pije76/.virtualenvs/justdial/lib/python3.6/site-packages/django/db/models/sql/query.py", line 1350, in add_q
    clause, _ = self._add_q(q_object, self.used_aliases)
  File "/home/pije76/.virtualenvs/justdial/lib/python3.6/site-packages/django/db/models/sql/query.py", line 1381, in _add_q
    check_filterable=check_filterable,
  File "/home/pije76/.virtualenvs/justdial/lib/python3.6/site-packages/django/db/models/sql/query.py", line 1311, in build_filter
    condition = self.build_lookup(lookups, col, value)
  File "/home/pije76/.virtualenvs/justdial/lib/python3.6/site-packages/django/db/models/sql/query.py", line 1156, in build_lookup
    raise FieldError('Related Field got invalid lookup: {}'.format(lookup_name))
django.core.exceptions.FieldError: Related Field got invalid lookup: icontains
Internal Server Error: /ajax_select/ajax_lookup/category
Traceback (most recent call last):
  File "/home/pije76/.virtualenvs/justdial/lib/python3.6/site-packages/django/core/handlers/exception.py", line 34, in inner
    response = get_response(request)
  File "/home/pije76/.virtualenvs/justdial/lib/python3.6/site-packages/django/core/handlers/base.py", line 115, in _get_response
    response = self.process_exception_by_middleware(e, request)
  File "/home/pije76/.virtualenvs/justdial/lib/python3.6/site-packages/django/core/handlers/base.py", line 113, in _get_response
    response = wrapped_callback(request, *callback_args, **callback_kwargs)
  File "/home/pije76/.virtualenvs/justdial/lib/python3.6/site-packages/ajax_select/views.py", line 36, in ajax_lookup
    instances = lookup.get_query(query, request)
  File "/var/www/html/justdial/listing/lookups.py", line 26, in get_query
    return self.model.objects.filter(category__icontains=q).order_by('category')[:50]
  File "/home/pije76/.virtualenvs/justdial/lib/python3.6/site-packages/django/db/models/manager.py", line 82, in manager_method
    return getattr(self.get_queryset(), name)(*args, **kwargs)
  File "/home/pije76/.virtualenvs/justdial/lib/python3.6/site-packages/django/db/models/query.py", line 904, in filter
    return self._filter_or_exclude(False, *args, **kwargs)
  File "/home/pije76/.virtualenvs/justdial/lib/python3.6/site-packages/django/db/models/query.py", line 923, in _filter_or_exclude
    clone.query.add_q(Q(*args, **kwargs))
  File "/home/pije76/.virtualenvs/justdial/lib/python3.6/site-packages/django/db/models/sql/query.py", line 1350, in add_q
    clause, _ = self._add_q(q_object, self.used_aliases)
  File "/home/pije76/.virtualenvs/justdial/lib/python3.6/site-packages/django/db/models/sql/query.py", line 1381, in _add_q
    check_filterable=check_filterable,
  File "/home/pije76/.virtualenvs/justdial/lib/python3.6/site-packages/django/db/models/sql/query.py", line 1311, in build_filter
    condition = self.build_lookup(lookups, col, value)
  File "/home/pije76/.virtualenvs/justdial/lib/python3.6/site-packages/django/db/models/sql/query.py", line 1156, in build_lookup
    raise FieldError('Related Field got invalid lookup: {}'.format(lookup_name))
django.core.exceptions.FieldError: Related Field got invalid lookup: icontains
Internal Server Error: /ajax_select/ajax_lookup/category
Traceback (most recent call last):
  File "/home/pije76/.virtualenvs/justdial/lib/python3.6/site-packages/django/core/handlers/exception.py", line 34, in inner
    response = get_response(request)
  File "/home/pije76/.virtualenvs/justdial/lib/python3.6/site-packages/django/core/handlers/base.py", line 115, in _get_response
    response = self.process_exception_by_middleware(e, request)
  File "/home/pije76/.virtualenvs/justdial/lib/python3.6/site-packages/django/core/handlers/base.py", line 113, in _get_response
    response = wrapped_callback(request, *callback_args, **callback_kwargs)
  File "/home/pije76/.virtualenvs/justdial/lib/python3.6/site-packages/ajax_select/views.py", line 36, in ajax_lookup
    instances = lookup.get_query(query, request)
  File "/var/www/html/justdial/listing/lookups.py", line 26, in get_query
    return self.model.objects.filter(category__icontains=q).order_by('category')[:50]
  File "/home/pije76/.virtualenvs/justdial/lib/python3.6/site-packages/django/db/models/manager.py", line 82, in manager_method
    return getattr(self.get_queryset(), name)(*args, **kwargs)
  File "/home/pije76/.virtualenvs/justdial/lib/python3.6/site-packages/django/db/models/query.py", line 904, in filter
    return self._filter_or_exclude(False, *args, **kwargs)
  File "/home/pije76/.virtualenvs/justdial/lib/python3.6/site-packages/django/db/models/query.py", line 923, in _filter_or_exclude
    clone.query.add_q(Q(*args, **kwargs))
  File "/home/pije76/.virtualenvs/justdial/lib/python3.6/site-packages/django/db/models/sql/query.py", line 1350, in add_q
    clause, _ = self._add_q(q_object, self.used_aliases)
  File "/home/pije76/.virtualenvs/justdial/lib/python3.6/site-packages/django/db/models/sql/query.py", line 1381, in _add_q
    check_filterable=check_filterable,
  File "/home/pije76/.virtualenvs/justdial/lib/python3.6/site-packages/django/db/models/sql/query.py", line 1311, in build_filter
    condition = self.build_lookup(lookups, col, value)
  File "/home/pije76/.virtualenvs/justdial/lib/python3.6/site-packages/django/db/models/sql/query.py", line 1156, in build_lookup
    raise FieldError('Related Field got invalid lookup: {}'.format(lookup_name))
django.core.exceptions.FieldError: Related Field got invalid lookup: icontains
Internal Server Error: /ajax_select/ajax_lookup/category
Traceback (most recent call last):
  File "/home/pije76/.virtualenvs/justdial/lib/python3.6/site-packages/django/core/handlers/exception.py", line 34, in inner
    response = get_response(request)
  File "/home/pije76/.virtualenvs/justdial/lib/python3.6/site-packages/django/core/handlers/base.py", line 115, in _get_response
    response = self.process_exception_by_middleware(e, request)
  File "/home/pije76/.virtualenvs/justdial/lib/python3.6/site-packages/django/core/handlers/base.py", line 113, in _get_response
    response = wrapped_callback(request, *callback_args, **callback_kwargs)
  File "/home/pije76/.virtualenvs/justdial/lib/python3.6/site-packages/ajax_select/views.py", line 36, in ajax_lookup
    instances = lookup.get_query(query, request)
  File "/var/www/html/justdial/listing/lookups.py", line 26, in get_query
    return self.model.objects.filter(category__icontains=q).order_by('category')[:50]
  File "/home/pije76/.virtualenvs/justdial/lib/python3.6/site-packages/django/db/models/manager.py", line 82, in manager_method
    return getattr(self.get_queryset(), name)(*args, **kwargs)
  File "/home/pije76/.virtualenvs/justdial/lib/python3.6/site-packages/django/db/models/query.py", line 904, in filter
    return self._filter_or_exclude(False, *args, **kwargs)
  File "/home/pije76/.virtualenvs/justdial/lib/python3.6/site-packages/django/db/models/query.py", line 923, in _filter_or_exclude
    clone.query.add_q(Q(*args, **kwargs))
  File "/home/pije76/.virtualenvs/justdial/lib/python3.6/site-packages/django/db/models/sql/query.py", line 1350, in add_q
    clause, _ = self._add_q(q_object, self.used_aliases)
  File "/home/pije76/.virtualenvs/justdial/lib/python3.6/site-packages/django/db/models/sql/query.py", line 1381, in _add_q
    check_filterable=check_filterable,
  File "/home/pije76/.virtualenvs/justdial/lib/python3.6/site-packages/django/db/models/sql/query.py", line 1311, in build_filter
    condition = self.build_lookup(lookups, col, value)
  File "/home/pije76/.virtualenvs/justdial/lib/python3.6/site-packages/django/db/models/sql/query.py", line 1156, in build_lookup
    raise FieldError('Related Field got invalid lookup: {}'.format(lookup_name))
django.core.exceptions.FieldError: Related Field got invalid lookup: icontains
Internal Server Error: /ajax_select/ajax_lookup/category
Traceback (most recent call last):
  File "/home/pije76/.virtualenvs/justdial/lib/python3.6/site-packages/django/core/handlers/exception.py", line 34, in inner
    response = get_response(request)
  File "/home/pije76/.virtualenvs/justdial/lib/python3.6/site-packages/django/core/handlers/base.py", line 115, in _get_response
    response = self.process_exception_by_middleware(e, request)
  File "/home/pije76/.virtualenvs/justdial/lib/python3.6/site-packages/django/core/handlers/base.py", line 113, in _get_response
    response = wrapped_callback(request, *callback_args, **callback_kwargs)
  File "/home/pije76/.virtualenvs/justdial/lib/python3.6/site-packages/ajax_select/views.py", line 36, in ajax_lookup
    instances = lookup.get_query(query, request)
  File "/var/www/html/justdial/listing/lookups.py", line 26, in get_query
    return self.model.objects.filter(category__icontains=q)
  File "/home/pije76/.virtualenvs/justdial/lib/python3.6/site-packages/django/db/models/manager.py", line 82, in manager_method
    return getattr(self.get_queryset(), name)(*args, **kwargs)
  File "/home/pije76/.virtualenvs/justdial/lib/python3.6/site-packages/django/db/models/query.py", line 904, in filter
    return self._filter_or_exclude(False, *args, **kwargs)
  File "/home/pije76/.virtualenvs/justdial/lib/python3.6/site-packages/django/db/models/query.py", line 923, in _filter_or_exclude
    clone.query.add_q(Q(*args, **kwargs))
  File "/home/pije76/.virtualenvs/justdial/lib/python3.6/site-packages/django/db/models/sql/query.py", line 1350, in add_q
    clause, _ = self._add_q(q_object, self.used_aliases)
  File "/home/pije76/.virtualenvs/justdial/lib/python3.6/site-packages/django/db/models/sql/query.py", line 1381, in _add_q
    check_filterable=check_filterable,
  File "/home/pije76/.virtualenvs/justdial/lib/python3.6/site-packages/django/db/models/sql/query.py", line 1311, in build_filter
    condition = self.build_lookup(lookups, col, value)
  File "/home/pije76/.virtualenvs/justdial/lib/python3.6/site-packages/django/db/models/sql/query.py", line 1156, in build_lookup
    raise FieldError('Related Field got invalid lookup: {}'.format(lookup_name))
django.core.exceptions.FieldError: Related Field got invalid lookup: icontains
Internal Server Error: /ajax_select/ajax_lookup/category
Traceback (most recent call last):
  File "/home/pije76/.virtualenvs/justdial/lib/python3.6/site-packages/django/core/handlers/exception.py", line 34, in inner
    response = get_response(request)
  File "/home/pije76/.virtualenvs/justdial/lib/python3.6/site-packages/django/core/handlers/base.py", line 115, in _get_response
    response = self.process_exception_by_middleware(e, request)
  File "/home/pije76/.virtualenvs/justdial/lib/python3.6/site-packages/django/core/handlers/base.py", line 113, in _get_response
    response = wrapped_callback(request, *callback_args, **callback_kwargs)
  File "/home/pije76/.virtualenvs/justdial/lib/python3.6/site-packages/ajax_select/views.py", line 36, in ajax_lookup
    instances = lookup.get_query(query, request)
  File "/var/www/html/justdial/listing/lookups.py", line 26, in get_query
    return self.model.objects.filter(category__icontains=q)
  File "/home/pije76/.virtualenvs/justdial/lib/python3.6/site-packages/django/db/models/manager.py", line 82, in manager_method
    return getattr(self.get_queryset(), name)(*args, **kwargs)
  File "/home/pije76/.virtualenvs/justdial/lib/python3.6/site-packages/django/db/models/query.py", line 904, in filter
    return self._filter_or_exclude(False, *args, **kwargs)
  File "/home/pije76/.virtualenvs/justdial/lib/python3.6/site-packages/django/db/models/query.py", line 923, in _filter_or_exclude
    clone.query.add_q(Q(*args, **kwargs))
  File "/home/pije76/.virtualenvs/justdial/lib/python3.6/site-packages/django/db/models/sql/query.py", line 1350, in add_q
    clause, _ = self._add_q(q_object, self.used_aliases)
  File "/home/pije76/.virtualenvs/justdial/lib/python3.6/site-packages/django/db/models/sql/query.py", line 1381, in _add_q
    check_filterable=check_filterable,
  File "/home/pije76/.virtualenvs/justdial/lib/python3.6/site-packages/django/db/models/sql/query.py", line 1311, in build_filter
    condition = self.build_lookup(lookups, col, value)
  File "/home/pije76/.virtualenvs/justdial/lib/python3.6/site-packages/django/db/models/sql/query.py", line 1156, in build_lookup
    raise FieldError('Related Field got invalid lookup: {}'.format(lookup_name))
django.core.exceptions.FieldError: Related Field got invalid lookup: icontains
Internal Server Error: /ajax_select/ajax_lookup/category
Traceback (most recent call last):
  File "/home/pije76/.virtualenvs/justdial/lib/python3.6/site-packages/django/core/handlers/exception.py", line 34, in inner
    response = get_response(request)
  File "/home/pije76/.virtualenvs/justdial/lib/python3.6/site-packages/django/core/handlers/base.py", line 115, in _get_response
    response = self.process_exception_by_middleware(e, request)
  File "/home/pije76/.virtualenvs/justdial/lib/python3.6/site-packages/django/core/handlers/base.py", line 113, in _get_response
    response = wrapped_callback(request, *callback_args, **callback_kwargs)
  File "/home/pije76/.virtualenvs/justdial/lib/python3.6/site-packages/ajax_select/views.py", line 36, in ajax_lookup
    instances = lookup.get_query(query, request)
  File "/var/www/html/justdial/listing/lookups.py", line 26, in get_query
    return self.model.objects.filter(category__icontains=q)
  File "/home/pije76/.virtualenvs/justdial/lib/python3.6/site-packages/django/db/models/manager.py", line 82, in manager_method
    return getattr(self.get_queryset(), name)(*args, **kwargs)
  File "/home/pije76/.virtualenvs/justdial/lib/python3.6/site-packages/django/db/models/query.py", line 904, in filter
    return self._filter_or_exclude(False, *args, **kwargs)
  File "/home/pije76/.virtualenvs/justdial/lib/python3.6/site-packages/django/db/models/query.py", line 923, in _filter_or_exclude
    clone.query.add_q(Q(*args, **kwargs))
  File "/home/pije76/.virtualenvs/justdial/lib/python3.6/site-packages/django/db/models/sql/query.py", line 1350, in add_q
    clause, _ = self._add_q(q_object, self.used_aliases)
  File "/home/pije76/.virtualenvs/justdial/lib/python3.6/site-packages/django/db/models/sql/query.py", line 1381, in _add_q
    check_filterable=check_filterable,
  File "/home/pije76/.virtualenvs/justdial/lib/python3.6/site-packages/django/db/models/sql/query.py", line 1311, in build_filter
    condition = self.build_lookup(lookups, col, value)
  File "/home/pije76/.virtualenvs/justdial/lib/python3.6/site-packages/django/db/models/sql/query.py", line 1156, in build_lookup
    raise FieldError('Related Field got invalid lookup: {}'.format(lookup_name))
django.core.exceptions.FieldError: Related Field got invalid lookup: icontains
Internal Server Error: /ajax_select/ajax_lookup/category
Traceback (most recent call last):
  File "/home/pije76/.virtualenvs/justdial/lib/python3.6/site-packages/django/core/handlers/exception.py", line 34, in inner
    response = get_response(request)
  File "/home/pije76/.virtualenvs/justdial/lib/python3.6/site-packages/django/core/handlers/base.py", line 115, in _get_response
    response = self.process_exception_by_middleware(e, request)
  File "/home/pije76/.virtualenvs/justdial/lib/python3.6/site-packages/django/core/handlers/base.py", line 113, in _get_response
    response = wrapped_callback(request, *callback_args, **callback_kwargs)
  File "/home/pije76/.virtualenvs/justdial/lib/python3.6/site-packages/ajax_select/views.py", line 36, in ajax_lookup
    instances = lookup.get_query(query, request)
  File "/var/www/html/justdial/listing/lookups.py", line 26, in get_query
    return self.model.objects.filter(category__icontains=q)
  File "/home/pije76/.virtualenvs/justdial/lib/python3.6/site-packages/django/db/models/manager.py", line 82, in manager_method
    return getattr(self.get_queryset(), name)(*args, **kwargs)
  File "/home/pije76/.virtualenvs/justdial/lib/python3.6/site-packages/django/db/models/query.py", line 904, in filter
    return self._filter_or_exclude(False, *args, **kwargs)
  File "/home/pije76/.virtualenvs/justdial/lib/python3.6/site-packages/django/db/models/query.py", line 923, in _filter_or_exclude
    clone.query.add_q(Q(*args, **kwargs))
  File "/home/pije76/.virtualenvs/justdial/lib/python3.6/site-packages/django/db/models/sql/query.py", line 1350, in add_q
    clause, _ = self._add_q(q_object, self.used_aliases)
  File "/home/pije76/.virtualenvs/justdial/lib/python3.6/site-packages/django/db/models/sql/query.py", line 1381, in _add_q
    check_filterable=check_filterable,
  File "/home/pije76/.virtualenvs/justdial/lib/python3.6/site-packages/django/db/models/sql/query.py", line 1311, in build_filter
    condition = self.build_lookup(lookups, col, value)
  File "/home/pije76/.virtualenvs/justdial/lib/python3.6/site-packages/django/db/models/sql/query.py", line 1156, in build_lookup
    raise FieldError('Related Field got invalid lookup: {}'.format(lookup_name))
django.core.exceptions.FieldError: Related Field got invalid lookup: icontains
Internal Server Error: /ajax_select/ajax_lookup/category
Traceback (most recent call last):
  File "/home/pije76/.virtualenvs/justdial/lib/python3.6/site-packages/django/core/handlers/exception.py", line 34, in inner
    response = get_response(request)
  File "/home/pije76/.virtualenvs/justdial/lib/python3.6/site-packages/django/core/handlers/base.py", line 115, in _get_response
    response = self.process_exception_by_middleware(e, request)
  File "/home/pije76/.virtualenvs/justdial/lib/python3.6/site-packages/django/core/handlers/base.py", line 113, in _get_response
    response = wrapped_callback(request, *callback_args, **callback_kwargs)
  File "/home/pije76/.virtualenvs/justdial/lib/python3.6/site-packages/ajax_select/views.py", line 36, in ajax_lookup
    instances = lookup.get_query(query, request)
  File "/var/www/html/justdial/listing/lookups.py", line 26, in get_query
    return self.model.objects.filter(category__icontains=q)
  File "/home/pije76/.virtualenvs/justdial/lib/python3.6/site-packages/django/db/models/manager.py", line 82, in manager_method
    return getattr(self.get_queryset(), name)(*args, **kwargs)
  File "/home/pije76/.virtualenvs/justdial/lib/python3.6/site-packages/django/db/models/query.py", line 904, in filter
    return self._filter_or_exclude(False, *args, **kwargs)
  File "/home/pije76/.virtualenvs/justdial/lib/python3.6/site-packages/django/db/models/query.py", line 923, in _filter_or_exclude
    clone.query.add_q(Q(*args, **kwargs))
  File "/home/pije76/.virtualenvs/justdial/lib/python3.6/site-packages/django/db/models/sql/query.py", line 1350, in add_q
    clause, _ = self._add_q(q_object, self.used_aliases)
  File "/home/pije76/.virtualenvs/justdial/lib/python3.6/site-packages/django/db/models/sql/query.py", line 1381, in _add_q
    check_filterable=check_filterable,
  File "/home/pije76/.virtualenvs/justdial/lib/python3.6/site-packages/django/db/models/sql/query.py", line 1311, in build_filter
    condition = self.build_lookup(lookups, col, value)
  File "/home/pije76/.virtualenvs/justdial/lib/python3.6/site-packages/django/db/models/sql/query.py", line 1156, in build_lookup
    raise FieldError('Related Field got invalid lookup: {}'.format(lookup_name))
django.core.exceptions.FieldError: Related Field got invalid lookup: icontains
Internal Server Error: /ajax_select/ajax_lookup/category
Traceback (most recent call last):
  File "/home/pije76/.virtualenvs/justdial/lib/python3.6/site-packages/django/core/handlers/exception.py", line 34, in inner
    response = get_response(request)
  File "/home/pije76/.virtualenvs/justdial/lib/python3.6/site-packages/django/core/handlers/base.py", line 115, in _get_response
    response = self.process_exception_by_middleware(e, request)
  File "/home/pije76/.virtualenvs/justdial/lib/python3.6/site-packages/django/core/handlers/base.py", line 113, in _get_response
    response = wrapped_callback(request, *callback_args, **callback_kwargs)
  File "/home/pije76/.virtualenvs/justdial/lib/python3.6/site-packages/ajax_select/views.py", line 36, in ajax_lookup
    instances = lookup.get_query(query, request)
  File "/var/www/html/justdial/listing/lookups.py", line 26, in get_query
    return self.model.objects.filter(category__icontains=q)
  File "/home/pije76/.virtualenvs/justdial/lib/python3.6/site-packages/django/db/models/manager.py", line 82, in manager_method
    return getattr(self.get_queryset(), name)(*args, **kwargs)
  File "/home/pije76/.virtualenvs/justdial/lib/python3.6/site-packages/django/db/models/query.py", line 904, in filter
    return self._filter_or_exclude(False, *args, **kwargs)
  File "/home/pije76/.virtualenvs/justdial/lib/python3.6/site-packages/django/db/models/query.py", line 923, in _filter_or_exclude
    clone.query.add_q(Q(*args, **kwargs))
  File "/home/pije76/.virtualenvs/justdial/lib/python3.6/site-packages/django/db/models/sql/query.py", line 1350, in add_q
    clause, _ = self._add_q(q_object, self.used_aliases)
  File "/home/pije76/.virtualenvs/justdial/lib/python3.6/site-packages/django/db/models/sql/query.py", line 1381, in _add_q
    check_filterable=check_filterable,
  File "/home/pije76/.virtualenvs/justdial/lib/python3.6/site-packages/django/db/models/sql/query.py", line 1311, in build_filter
    condition = self.build_lookup(lookups, col, value)
  File "/home/pije76/.virtualenvs/justdial/lib/python3.6/site-packages/django/db/models/sql/query.py", line 1156, in build_lookup
    raise FieldError('Related Field got invalid lookup: {}'.format(lookup_name))
django.core.exceptions.FieldError: Related Field got invalid lookup: icontains
Internal Server Error: /ajax_select/ajax_lookup/category
Traceback (most recent call last):
  File "/home/pije76/.virtualenvs/justdial/lib/python3.6/site-packages/django/core/handlers/exception.py", line 34, in inner
    response = get_response(request)
  File "/home/pije76/.virtualenvs/justdial/lib/python3.6/site-packages/django/core/handlers/base.py", line 115, in _get_response
    response = self.process_exception_by_middleware(e, request)
  File "/home/pije76/.virtualenvs/justdial/lib/python3.6/site-packages/django/core/handlers/base.py", line 113, in _get_response
    response = wrapped_callback(request, *callback_args, **callback_kwargs)
  File "/home/pije76/.virtualenvs/justdial/lib/python3.6/site-packages/ajax_select/views.py", line 36, in ajax_lookup
    instances = lookup.get_query(query, request)
  File "/var/www/html/justdial/listing/lookups.py", line 26, in get_query
    return self.model.objects.filter(category__icontains=q)
  File "/home/pije76/.virtualenvs/justdial/lib/python3.6/site-packages/django/db/models/manager.py", line 82, in manager_method
    return getattr(self.get_queryset(), name)(*args, **kwargs)
  File "/home/pije76/.virtualenvs/justdial/lib/python3.6/site-packages/django/db/models/query.py", line 904, in filter
    return self._filter_or_exclude(False, *args, **kwargs)
  File "/home/pije76/.virtualenvs/justdial/lib/python3.6/site-packages/django/db/models/query.py", line 923, in _filter_or_exclude
    clone.query.add_q(Q(*args, **kwargs))
  File "/home/pije76/.virtualenvs/justdial/lib/python3.6/site-packages/django/db/models/sql/query.py", line 1350, in add_q
    clause, _ = self._add_q(q_object, self.used_aliases)
  File "/home/pije76/.virtualenvs/justdial/lib/python3.6/site-packages/django/db/models/sql/query.py", line 1381, in _add_q
    check_filterable=check_filterable,
  File "/home/pije76/.virtualenvs/justdial/lib/python3.6/site-packages/django/db/models/sql/query.py", line 1311, in build_filter
    condition = self.build_lookup(lookups, col, value)
  File "/home/pije76/.virtualenvs/justdial/lib/python3.6/site-packages/django/db/models/sql/query.py", line 1156, in build_lookup
    raise FieldError('Related Field got invalid lookup: {}'.format(lookup_name))
django.core.exceptions.FieldError: Related Field got invalid lookup: icontains
Internal Server Error: /ajax_select/ajax_lookup/category
Traceback (most recent call last):
  File "/home/pije76/.virtualenvs/justdial/lib/python3.6/site-packages/django/core/handlers/exception.py", line 34, in inner
    response = get_response(request)
  File "/home/pije76/.virtualenvs/justdial/lib/python3.6/site-packages/django/core/handlers/base.py", line 115, in _get_response
    response = self.process_exception_by_middleware(e, request)
  File "/home/pije76/.virtualenvs/justdial/lib/python3.6/site-packages/django/core/handlers/base.py", line 113, in _get_response
    response = wrapped_callback(request, *callback_args, **callback_kwargs)
  File "/home/pije76/.virtualenvs/justdial/lib/python3.6/site-packages/ajax_select/views.py", line 36, in ajax_lookup
    instances = lookup.get_query(query, request)
  File "/var/www/html/justdial/listing/lookups.py", line 26, in get_query
    return self.model.objects.filter(category__icontains=q)
  File "/home/pije76/.virtualenvs/justdial/lib/python3.6/site-packages/django/db/models/manager.py", line 82, in manager_method
    return getattr(self.get_queryset(), name)(*args, **kwargs)
  File "/home/pije76/.virtualenvs/justdial/lib/python3.6/site-packages/django/db/models/query.py", line 904, in filter
    return self._filter_or_exclude(False, *args, **kwargs)
  File "/home/pije76/.virtualenvs/justdial/lib/python3.6/site-packages/django/db/models/query.py", line 923, in _filter_or_exclude
    clone.query.add_q(Q(*args, **kwargs))
  File "/home/pije76/.virtualenvs/justdial/lib/python3.6/site-packages/django/db/models/sql/query.py", line 1350, in add_q
    clause, _ = self._add_q(q_object, self.used_aliases)
  File "/home/pije76/.virtualenvs/justdial/lib/python3.6/site-packages/django/db/models/sql/query.py", line 1381, in _add_q
    check_filterable=check_filterable,
  File "/home/pije76/.virtualenvs/justdial/lib/python3.6/site-packages/django/db/models/sql/query.py", line 1311, in build_filter
    condition = self.build_lookup(lookups, col, value)
  File "/home/pije76/.virtualenvs/justdial/lib/python3.6/site-packages/django/db/models/sql/query.py", line 1156, in build_lookup
    raise FieldError('Related Field got invalid lookup: {}'.format(lookup_name))
django.core.exceptions.FieldError: Related Field got invalid lookup: icontains
Internal Server Error: /ajax_select/ajax_lookup/category
Traceback (most recent call last):
  File "/home/pije76/.virtualenvs/justdial/lib/python3.6/site-packages/django/core/handlers/exception.py", line 34, in inner
    response = get_response(request)
  File "/home/pije76/.virtualenvs/justdial/lib/python3.6/site-packages/django/core/handlers/base.py", line 115, in _get_response
    response = self.process_exception_by_middleware(e, request)
  File "/home/pije76/.virtualenvs/justdial/lib/python3.6/site-packages/django/core/handlers/base.py", line 113, in _get_response
    response = wrapped_callback(request, *callback_args, **callback_kwargs)
  File "/home/pije76/.virtualenvs/justdial/lib/python3.6/site-packages/ajax_select/views.py", line 36, in ajax_lookup
    instances = lookup.get_query(query, request)
  File "/var/www/html/justdial/listing/lookups.py", line 26, in get_query
    return self.model.objects.filter(category__icontains=q)
  File "/home/pije76/.virtualenvs/justdial/lib/python3.6/site-packages/django/db/models/manager.py", line 82, in manager_method
    return getattr(self.get_queryset(), name)(*args, **kwargs)
  File "/home/pije76/.virtualenvs/justdial/lib/python3.6/site-packages/django/db/models/query.py", line 904, in filter
    return self._filter_or_exclude(False, *args, **kwargs)
  File "/home/pije76/.virtualenvs/justdial/lib/python3.6/site-packages/django/db/models/query.py", line 923, in _filter_or_exclude
    clone.query.add_q(Q(*args, **kwargs))
  File "/home/pije76/.virtualenvs/justdial/lib/python3.6/site-packages/django/db/models/sql/query.py", line 1350, in add_q
    clause, _ = self._add_q(q_object, self.used_aliases)
  File "/home/pije76/.virtualenvs/justdial/lib/python3.6/site-packages/django/db/models/sql/query.py", line 1381, in _add_q
    check_filterable=check_filterable,
  File "/home/pije76/.virtualenvs/justdial/lib/python3.6/site-packages/django/db/models/sql/query.py", line 1311, in build_filter
    condition = self.build_lookup(lookups, col, value)
  File "/home/pije76/.virtualenvs/justdial/lib/python3.6/site-packages/django/db/models/sql/query.py", line 1156, in build_lookup
    raise FieldError('Related Field got invalid lookup: {}'.format(lookup_name))
django.core.exceptions.FieldError: Related Field got invalid lookup: icontains
Internal Server Error: /privacy/
Traceback (most recent call last):
  File "/home/pije76/.virtualenvs/justdial/lib/python3.6/site-packages/django/db/models/fields/__init__.py", line 1772, in get_prep_value
    return int(value)
ValueError: invalid literal for int() with base 10: 'privacy'

The above exception was the direct cause of the following exception:

Traceback (most recent call last):
  File "/home/pije76/.virtualenvs/justdial/lib/python3.6/site-packages/django/core/handlers/exception.py", line 34, in inner
    response = get_response(request)
  File "/home/pije76/.virtualenvs/justdial/lib/python3.6/site-packages/django/core/handlers/base.py", line 115, in _get_response
    response = self.process_exception_by_middleware(e, request)
  File "/home/pije76/.virtualenvs/justdial/lib/python3.6/site-packages/django/core/handlers/base.py", line 113, in _get_response
    response = wrapped_callback(request, *callback_args, **callback_kwargs)
  File "/var/www/html/justdial/listing/views.py", line 40, in region_list
    country_name = Country.objects.filter(id=country_id)
  File "/home/pije76/.virtualenvs/justdial/lib/python3.6/site-packages/django/db/models/manager.py", line 82, in manager_method
    return getattr(self.get_queryset(), name)(*args, **kwargs)
  File "/home/pije76/.virtualenvs/justdial/lib/python3.6/site-packages/django/db/models/query.py", line 904, in filter
    return self._filter_or_exclude(False, *args, **kwargs)
  File "/home/pije76/.virtualenvs/justdial/lib/python3.6/site-packages/django/db/models/query.py", line 923, in _filter_or_exclude
    clone.query.add_q(Q(*args, **kwargs))
  File "/home/pije76/.virtualenvs/justdial/lib/python3.6/site-packages/django/db/models/sql/query.py", line 1350, in add_q
    clause, _ = self._add_q(q_object, self.used_aliases)
  File "/home/pije76/.virtualenvs/justdial/lib/python3.6/site-packages/django/db/models/sql/query.py", line 1381, in _add_q
    check_filterable=check_filterable,
  File "/home/pije76/.virtualenvs/justdial/lib/python3.6/site-packages/django/db/models/sql/query.py", line 1311, in build_filter
    condition = self.build_lookup(lookups, col, value)
  File "/home/pije76/.virtualenvs/justdial/lib/python3.6/site-packages/django/db/models/sql/query.py", line 1165, in build_lookup
    lookup = lookup_class(lhs, rhs)
  File "/home/pije76/.virtualenvs/justdial/lib/python3.6/site-packages/django/db/models/lookups.py", line 22, in __init__
    self.rhs = self.get_prep_lookup()
  File "/home/pije76/.virtualenvs/justdial/lib/python3.6/site-packages/django/db/models/lookups.py", line 72, in get_prep_lookup
    return self.lhs.output_field.get_prep_value(self.rhs)
  File "/home/pije76/.virtualenvs/justdial/lib/python3.6/site-packages/django/db/models/fields/__init__.py", line 1776, in get_prep_value
    ) from e
ValueError: Field 'id' expected a number but got 'privacy'.
Internal Server Error: /privacy/
Traceback (most recent call last):
  File "/home/pije76/.virtualenvs/justdial/lib/python3.6/site-packages/django/db/models/fields/__init__.py", line 1772, in get_prep_value
    return int(value)
ValueError: invalid literal for int() with base 10: 'privacy'

The above exception was the direct cause of the following exception:

Traceback (most recent call last):
  File "/home/pije76/.virtualenvs/justdial/lib/python3.6/site-packages/django/core/handlers/exception.py", line 34, in inner
    response = get_response(request)
  File "/home/pije76/.virtualenvs/justdial/lib/python3.6/site-packages/django/core/handlers/base.py", line 115, in _get_response
    response = self.process_exception_by_middleware(e, request)
  File "/home/pije76/.virtualenvs/justdial/lib/python3.6/site-packages/django/core/handlers/base.py", line 113, in _get_response
    response = wrapped_callback(request, *callback_args, **callback_kwargs)
  File "/var/www/html/justdial/listing/views.py", line 40, in region_list
    country_name = Country.objects.filter(id=country_id)
  File "/home/pije76/.virtualenvs/justdial/lib/python3.6/site-packages/django/db/models/manager.py", line 82, in manager_method
    return getattr(self.get_queryset(), name)(*args, **kwargs)
  File "/home/pije76/.virtualenvs/justdial/lib/python3.6/site-packages/django/db/models/query.py", line 904, in filter
    return self._filter_or_exclude(False, *args, **kwargs)
  File "/home/pije76/.virtualenvs/justdial/lib/python3.6/site-packages/django/db/models/query.py", line 923, in _filter_or_exclude
    clone.query.add_q(Q(*args, **kwargs))
  File "/home/pije76/.virtualenvs/justdial/lib/python3.6/site-packages/django/db/models/sql/query.py", line 1350, in add_q
    clause, _ = self._add_q(q_object, self.used_aliases)
  File "/home/pije76/.virtualenvs/justdial/lib/python3.6/site-packages/django/db/models/sql/query.py", line 1381, in _add_q
    check_filterable=check_filterable,
  File "/home/pije76/.virtualenvs/justdial/lib/python3.6/site-packages/django/db/models/sql/query.py", line 1311, in build_filter
    condition = self.build_lookup(lookups, col, value)
  File "/home/pije76/.virtualenvs/justdial/lib/python3.6/site-packages/django/db/models/sql/query.py", line 1165, in build_lookup
    lookup = lookup_class(lhs, rhs)
  File "/home/pije76/.virtualenvs/justdial/lib/python3.6/site-packages/django/db/models/lookups.py", line 22, in __init__
    self.rhs = self.get_prep_lookup()
  File "/home/pije76/.virtualenvs/justdial/lib/python3.6/site-packages/django/db/models/lookups.py", line 72, in get_prep_lookup
    return self.lhs.output_field.get_prep_value(self.rhs)
  File "/home/pije76/.virtualenvs/justdial/lib/python3.6/site-packages/django/db/models/fields/__init__.py", line 1776, in get_prep_value
    ) from e
ValueError: Field 'id' expected a number but got 'privacy'.
Internal Server Error: /privacy/
Traceback (most recent call last):
  File "/home/pije76/.virtualenvs/justdial/lib/python3.6/site-packages/django/core/handlers/exception.py", line 34, in inner
    response = get_response(request)
  File "/home/pije76/.virtualenvs/justdial/lib/python3.6/site-packages/django/core/handlers/base.py", line 115, in _get_response
    response = self.process_exception_by_middleware(e, request)
  File "/home/pije76/.virtualenvs/justdial/lib/python3.6/site-packages/django/core/handlers/base.py", line 113, in _get_response
    response = wrapped_callback(request, *callback_args, **callback_kwargs)
  File "/var/www/html/justdial/listing/views.py", line 41, in privacy
    return render(request, "privacy.html", context)
  File "/home/pije76/.virtualenvs/justdial/lib/python3.6/site-packages/django/shortcuts.py", line 19, in render
    content = loader.render_to_string(template_name, context, request, using=using)
  File "/home/pije76/.virtualenvs/justdial/lib/python3.6/site-packages/django/template/loader.py", line 61, in render_to_string
    template = get_template(template_name, using=using)
  File "/home/pije76/.virtualenvs/justdial/lib/python3.6/site-packages/django/template/loader.py", line 19, in get_template
    raise TemplateDoesNotExist(template_name, chain=chain)
django.template.exceptions.TemplateDoesNotExist: privacy.html
